Workbook

Sheet Hoja 1
A1: Prioridad | B1: Nombre del Logro | C1: Link Wiki | D1: Categoria | E1: Dificultad | F1: Tipo de Tiempo | G1: Que hacer exactamente | H1: Completado
A2: 01. EMPEZAR HOY | B2: Port Life | C2: =VLOOKUP(B2, runescape_achievements!A:G, 7, FALSE) -> https://runescape.wiki/w/Port_Life | D2: Player Owned Port | E2: Facil | F2: Time-Gated | G2: Habla con el Portmaster en Port Sarim y completa el tutorial. | H2: TRUE
A3: 07. META FINAL | B3: Music Maestro | C3: =VLOOKUP(B3, runescape_achievements!A:G, 7, FALSE) -> https://runescape.wiki/w/Music_Maestro | D3: Activities | E3: Dificil | F3: Exploracion | G3: Desbloquea las 1 | H3: FALSE
A4: 07. META FINAL | B4: Task Master | C4: =VLOOKUP(B4, runescape_achievements!A:G, 7, FALSE) -> https://runescape.wiki/w/Task_Master | D4: Area Tasks | E4: Dificil | F4: Grind Largo | G4: Completa TODOS los logros de área (Easy Medium Hard y Elite) de todas las regiones. | H4: FALSE
A5: 01. EMPEZAR HOY | B5: Top Town Hall | C5: =VLOOKUP(B5, runescape_achievements!A:G, 7, FALSE) -> https://runescape.wiki/w/Top_Town_Hall | D5: Exploration | E5: Facil | F5: Time-Gated | G5: Asigna trabajadores y junta recursos diarios en Anachronia para subir el Town Hall a T3. | H5: TRUE
A6: 06. PVM & COMBATE | B6: Annihilator | C6: =VLOOKUP(B6, runescape_achievements!A:G, 7, FALSE) -> https://runescape.wiki/w/Annihilator | D6: Lore | E6: Dificil | F6: Combate | G6: Ataca a los 4 Nihils a la vez (Sombre Ice Blood Smoke) y mátalos en el mismo combate. | H6: FALSE
A7: 07. META FINAL | B7: I've Got a Little List (of Miniquests) | C7: =VLOOKUP(B7, runescape_achievements!A:G, 7, FALSE) -> https://runescape.wiki/w/I%27ve_Got_a_Little_List_(of_Miniquests) | D7: Lore | E7: Dificil | F7: Misiones | G7: Completa TODAS las miniquests secundarias del diario. | H7: FALSE
A8: 06. PVM & COMBATE | B8: Slayer Master | C8: =VLOOKUP(B8, runescape_achievements!A:G, 7, FALSE) -> https://runescape.wiki/w/Slayer_Master_(achievement) | D8: Skills | E8: Dificil | F8: Combate | G8: Alcanza la ola requerida en la dificultad Platinum de Rush of Blood. | H8: FALSE
A9: 02. REGALADOS | B9: Undead to Rites | C9: =VLOOKUP(B9, runescape_achievements!A:G, 7, FALSE) -> https://runescape.wiki/w/Undead_to_Rites | D9: Area Tasks | E9: Facil | F9: Inmediato | G9: Usa el encantamiento "Ungael Teleport" para aparecer en el sitio del ritual. | H9: TRUE
A10: 07. META FINAL | B10: Master Skiller | C10: =VLOOKUP(B10, runescape_achievements!A:G, 7, FALSE) -> https://runescape.wiki/w/Master_Skiller | D10: Skills | E10: Dificil | F10: Grind Largo | G10: Sube todas las habilidades a sus niveles máximos (120 en aplicables 99 en el resto). | H10: FALSE
A11: 02. REGALADOS | B11: Slide To The Left | C11: =VLOOKUP(B11, runescape_achievements!A:G, 7, FALSE) -> https://runescape.wiki/w/Slide_To_The_Left | D11: Treasure Trails | E11: Facil | F11: Inmediato | G11: Resuelve un puzle de deslizamiento (Slide Box) con Alt1. | H11: TRUE
A12: 03. SKILLING & MID | B12: Bill & Ben's Egg/Salon Joint Venture | C12: =VLOOKUP(B12, runescape_achievements!A:G, 7, FALSE) -> https://runescape.wiki/w/Bill_%26_Ben%27s_Egg/Salon_Joint_Venture | D12: Activities | E12: Facil | F12: Inmediato | G12: Tras la misión Extinction | H12: FALSE
A13: 02. REGALADOS | B13: Untangled | C13: =VLOOKUP(B13, runescape_achievements!A:G, 7, FALSE) -> https://runescape.wiki/w/Untangled | D13: Treasure Trails | E13: Facil | F13: Inmediato | G13: Resuelve un puzle de nudo céltico (Celtic Knot) con Alt1. | H13: TRUE
... A103: 03. SKILLING & MID | B103: Gaps, Traps and Laps | C103: =VLOOKUP(B103, runescape_achievements!A:G, 7, FALSE) -> https://runescape.wiki/w/Gaps,_Traps_and_Laps | D103: _Traps_and_Laps | E103: Skills | F103: Media | G103: Grind Corto | H103: FALSE

Sheet runescape_achievements
A1: Name | B1: Description | C1: Category | D1: Subcategory | E1: Subsubcategory | F1: Release date | G1: Wiki Link
A2: Phite Club | B2: Complete this quest. | C2: Lore | D2: Quests | F2: 5 June 2017 | G2: https://runescape.wiki/w/%27Phite_Club_(achievement)
A3: Phite for Your Right I | B3: Complete a city quest from an inhabitant of Menaphos. | C3: Exploration | D3: Menaphos | F3: 5 June 2017 | G3: https://runescape.wiki/w/%27Phite_for_Your_Right_I
A4: Phite for Your Right II | B4: Complete 10 city quests from an inhabitant of Menaphos. (X/10) | C4: Exploration | D4: Menaphos | F4: 5 June 2017 | G4: https://runescape.wiki/w/%27Phite_for_Your_Right_II
A5: Phite for Your Right III | B5: Complete 50 city quests from an inhabitant of Menaphos. (X/50) | C5: Exploration | D5: Menaphos | F5: 5 June 2017 | G5: https://runescape.wiki/w/%27Phite_for_Your_Right_III
A6: Phite for Your Right IV | B6: Complete 100 city quests from an inhabitant of Menaphos. (X/100) | C6: Exploration | D6: Menaphos | F6: 5 June 2017 | G6: https://runescape.wiki/w/%27Phite_for_Your_Right_IV
A7: Phite for Your Right V | B7: Complete 200 city quests from an inhabitant of Menaphos. (X/200) | C7: Exploration | D7: Menaphos | F7: 5 June 2017 | G7: https://runescape.wiki/w/%27Phite_for_Your_Right_V
A8: (Do Not) Abandon Hope I | B8: Complete an abandoned 1 floor within 12 minutes. Requirements: 1:1 party size:difficulty, large dungeon, high complexity, 100% explored | C8: Skills | D8: Dungeoneering | E8: Speedrunning | F8: 46160 | G8: https://runescape.wiki/w/(Do_Not)_Abandon_Hope_I
A9: (Do Not) Abandon Hope II | B9: Complete an abandoned 1 floor within 8 minutes. Requirements: 1:1 party size:difficulty, large dungeon, high complexity, 100% explored | C9: Skills | D9: Dungeoneering | E9: Speedrunning | F9: 46160 | G9: https://runescape.wiki/w/(Do_Not)_Abandon_Hope_II
A10: (Do Not) Abandon Hope III | B10: Complete an abandoned 1 floor within 6 minutes 15 seconds. Requirements: 1:1 party size:difficulty, large dungeon, high complexity, 100% explored | C10: Skills | D10: Dungeoneering | E10: Speedrunning | F10: 46160 | G10: https://runescape.wiki/w/(Do_Not)_Abandon_Hope_III
A11: (Living on a) Prayer 92 | B11: Reach level 92 in the Prayer skill. | C11: Skills | D11: Prayer | F11: 18 April 2017 | G11: https://runescape.wiki/w/(Living_on_a)_Prayer_92
A12: ...You'd Best Come A-cookin' | B12: Cook a rocktail on a range in the Falador area. | C12: Area Tasks | D12: Elite Falador | F12: 7 September 2010 | G12: https://runescape.wiki/w/...You%27d_Best_Come_A-cookin%27
A13: 61 Shades of Red | B13: Obtained a collection of unique drops from Slayer monsters from and around Daemonheim. | C13: Feats | D13: Slayer Logs | F13: 23 September 2019 | G13: https://runescape.wiki/w/61_Shades_of_Red
A14: 99 With a Flake | B14: Unfurl a flag in the Max Guild garden or jump for joy if you have already unfurled them all. | C14: Area Tasks | D14: Elite Tirannwn | F14: 15 December 2014 | G14: https://runescape.wiki/w/99_With_a_Flake
A15: 300 | B15: Complete Three's Company with 100%. | C15: Area Tasks | D15: Medium Daemonheim | F15: 10 September 2013 | G15: https://runescape.wiki/w/300
A16: 1001 Kharidian Spikes | B16: Harvest spines from a cactus you grew yourself in Al Kharid. | C16: Area Tasks | D16: Hard Desert | F16: 21 January 2013 | G16: https://runescape.wiki/w/1001_Kharidian_Spikes
A17: A Barrel of Staffs | B17: Purchase a God staff from the Chamber guardian in the Mage Arena. | C17: Area Tasks | D17: Medium Wilderness | F17: 8 August 2016 | G17: https://runescape.wiki/w/A_Barrel_of_Staffs
A18: A Bit TOO Familiar | B18: Play as the following familiars in Familiarisation. | C18: Activities | D18: Distractions & Diversions | F18: 5 November 2018 | G18: https://runescape.wiki/w/A_Bit_TOO_Familiar
A19: A Blight of Bloom and Hatchets | B19: Work with Ramarno (in Camdozaal) to obtain a hatchet of bloom and blight. (X/9) | C19: Skills | D19: Woodcutting | F19: 9 December 2024 | G19: https://runescape.wiki/w/A_Blight_of_Bloom_and_Hatchets
A20: A Body in the Sewers | B20: Smith a mithril platebody on the anvil in the jailhouse sewers. | C20: Area Tasks | D20: Hard Lumbridge | F20: 7 September 2010 | G20: https://runescape.wiki/w/A_Body_in_the_Sewers
A21: A Bolt from the Bane | B21: Smith and fletch 10 bane bolts at once within Varrock. | C21: Area Tasks | D21: Elite Varrock | F21: 7 September 2010 | G21: https://runescape.wiki/w/A_Bolt_from_the_Bane
A22: A Bridge Not Far | B22: Cross the River Lum using a crossbow. | C22: Area Tasks | D22: Medium Desert | F22: 21 January 2013 | G22: https://runescape.wiki/w/A_Bridge_Not_Far
A23: A Brief History of Telescopes | B23: Discover the pieces of a famous quote from Stephen Hawking. (X/4) | C23: Feats | D23: Events | F23: 19 March 2018 | G23: https://runescape.wiki/w/A_Brief_History_of_Telescopes
A24: A bug in the system | B24: Find and read the scruffy note in the Scabarite Cavern. | C24: Lore | D24: Books | F24: 25 November 2024 | G24: https://runescape.wiki/w/A_bug_in_the_system
A25: A Cat is For Life... | B25: Talk to a civilian in West Ardougne about selling a cat. | C25: Area Tasks | D25: Easy Ardougne | F25: 10 October 2009 | G25: https://runescape.wiki/w/A_Cat_is_For_Life...
A26: A Change of Pace | B26: Unlock the ability to change your spellbook using War's Grimoire at War's Retreat. | C26: Combat | D26: PvM Hub: War's Retreat | F26: 17 February 2025 | G26: https://runescape.wiki/w/A_Change_of_Pace
A27: A Charm Saved is a Charm Earned | B27: Charge or combine a spirit gem. | C27: Skills | D27: Summoning | F27: 5 November 2018 | G27: https://runescape.wiki/w/A_Charm_Saved_is_a_Charm_Earned
... A47: A Grave Consideration | B47: Look through Father Aereck's selection of gravestones. | C47: Area Tasks | D47: Beginner Lumbridge | F47: 14 July 2008 | G47: https://runescape.wiki/w/A_Grave_Consideration
A48: A Hatching Pair | B48: After Extinction quest, ask Prehistoric Potterington at the Anachronia dinosaur farm about zygomites. | C48: Activities | D48: Accidental' Skilling Station | F48: 44684 | G48: https://runescape.wiki/w/A_Hatching_Pair
A49: A Hidden Gem I | B49: Shatter a crystal geode. (X/1) | C49: Skills | D49: Woodcutting | F49: 5 November 2018 | G49: https://runescape.wiki/w/A_Hidden_Gem_I
A50: A Hidden Gem II | B50: Shatter 5 crystal geodes. (X/5) | C50: Skills | D50: Woodcutting | F50: 5 November 2018 | G50: https://runescape.wiki/w/A_Hidden_Gem_II
A51: A Hidden Gem III | B51: Shatter 10 crystal geodes. (X/10) | C51: Skills | D51: Woodcutting | F51: 5 November 2018 | G51: https://runescape.wiki/w/A_Hidden_Gem_III
A52: A Hidden Gem IV | B52: Shatter 25 crystal geodes. (X/25) | C52: Skills | D52: Woodcutting | F52: 5 November 2018 | G52: https://runescape.wiki/w/A_Hidden_Gem_IV
A53: A Knight in the Darkness | B53: Ascend the Dark Wizards' Tower while wearing full proselyte armour. | C53: Area Tasks | D53: Hard Falador | F53: 9 December 2008 | G53: https://runescape.wiki/w/A_Knight_in_the_Darkness
A54: A Lick of Paint | B54: Select a colour for a new kitten. | C54: Area Tasks | D54: Medium Varrock | F54: 10 September 2007 | G54: https://runescape.wiki/w/A_Lick_of_Paint
A55: A Life of Death and Pickaxes | B55: Work with Ramarno (in Camdozaal) to obtain a pickaxe of life and death. (X/9) | C55: Skills | D55: Mining | F55: 12 August 2024 | G55: https://runescape.wiki/w/A_Life_of_Death_and_Pickaxes
A56: A Little Overdressed | B56: Wear a full diving outfit to go diving in Everlight. | C56: Skills | D56: Archaeology | E56: Saradominist | F56: 30 March 2020 | G56: https://runescape.wiki/w/A_Little_Overdressed
A57: A Meal Fit For a Duke | B57: Cook a lobster on the range in Lumbridge Castle's kitchen. | C57: Area Tasks | D57: Medium Lumbridge | F57: 14 July 2008 | G57: https://runescape.wiki/w/A_Meal_Fit_For_a_Duke
A58: A Mini Shipment | B58: Loot the trunk in the Temple of Aminishi. | C58: Combat | D58: Shadow Reef | F58: 25 February 2019 | G58: https://runescape.wiki/w/A_Mini_Shipment
A59: A Natural Thief | B59: Attempt to steal a nature rune from a chest in a house to the east of Ardougne market. | C59: Area Tasks | D59: Medium Ardougne | F59: 10 October 2009 | G59: https://runescape.wiki/w/A_Natural_Thief
...
